Workbook
Name isak: [1]Sayfa2!$B:$M

Sheet 5600M
C3: T R E N H A R E K E T B İ L D İ R İ M F O R M U
C5: KKY Sipariş No | G5: Sefer Belge No | I5: 23215 | J5: no.lu trenin | Q5: tarih
Q6: =TODAY()
C8: çıkış | I8: varış | L8: saati | R8: uzunluk (mt)
C9: istasyonu | G9: kodu | I9: istasyonu | J9: kodu | L9: orer | M9: teslim | N9: sevk | O9: fren yüzdesi | P9: gerekli fren | R9: =IF(sf.V!R2>0,sf.V!R2,"")
C10: ARİFİYE | G10: 1512
C11: LOKO BİLGİLERİ | L11: AĞIRLIK BİLGİLERİ | O11: 41 | P11: =IF(L13<>"",ROUNDUP((L13*O11)/100,0),"") | R11: dingil adedi
C12: esas | F12: ön destek | I12: arka destek | L12: brüt | M12: net | N12: fren ağr. | R12: =SUM(D16:D64)
L13: =SUM(O16:O64) | M13: =SUM(N16:N64) | N13: =SUM(P16:P64)
C14: DİZİDEKİ VAGONLARIN
C15: sıra no. | D15: dingili | E15: tipi | F15: dğş rejimi shp.idare | G15: vagon no | I15: yükün cinsi | J15: çıkış istasyonu | L15: varış istasyonu | N15: net ağırlık | O15: brüt ağırlık | P15: hava fren | Q15: sıra no. | R15: bırakıldığı istasyon
C16: 1 | D16: =IF(G16<>"",VLOOKUP(G16,sf.V!$A$3:$K$124,3,FALSE),"") | E16: =IF(G16<>"",VLOOKUP(G16,sf.V!$A$3:$K$124,2,FALSE),"") | F16: 3175 | G16: 4569 | H16: 183-2 | J16: ARİFİYE | L16: KÖRFEZ | O16: =IF(G16<>"",VLOOKUP(G16,sf.V!$A$3:$K$124,6,FALSE)+N16,"") | P16: =IF(G16="","",IF(O16<T16,VLOOKUP(G16,sf.V!$A$3:$K$124,9,FALSE),IF(O16>=T16,VLOOKUP(G16,sf.V!$A$3:$K$124,10,FALSE),""))) | T16: =IF(G16<>"",VLOOKUP(G16,sf.V!$A$3:$K$124,11,FALSE),"")
C17: 2 | D17: =IF(G17<>"",VLOOKUP(G17,sf.V!$A$3:$K$124,3,FALSE),"") | E17: =IF(G17<>"",VLOOKUP(G17,sf.V!$A$3:$K$124,2,FALSE),"") | F17: 3175 | G17: 4569 | H17: 781-2 | J17: ARİFİYE | L17: KÖRFEZ | O17: =IF(G17<>"",VLOOKUP(G17,sf.V!$A$3:$K$124,6,FALSE)+N17,"") | P17: =IF(G17="","",IF(O17<T17,VLOOKUP(G17,sf.V!$A$3:$K$124,9,FALSE),IF(O17>=T17,VLOOKUP(G17,sf.V!$A$3:$K$124,10,FALSE),""))) | T17: =IF(G17<>"",VLOOKUP(G17,sf.V!$A$3:$K$124,11,FALSE),"")
C18: 3 | D18: =IF(G18<>"",VLOOKUP(G18,sf.V!$A$3:$K$124,3,FALSE),"") | E18: =IF(G18<>"",VLOOKUP(G18,sf.V!$A$3:$K$124,2,FALSE),"") | F18: 3175 | G18: 4594 | H18: 065-0 | J18: ARİFİYE | L18: KÖRFEZ | O18: =IF(G18<>"",VLOOKUP(G18,sf.V!$A$3:$K$124,6,FALSE)+N18,"") | P18: =IF(G18="","",IF(O18<T18,VLOOKUP(G18,sf.V!$A$3:$K$124,9,FALSE),IF(O18>=T18,VLOOKUP(G18,sf.V!$A$3:$K$124,10,FALSE),""))) | T18: =IF(G18<>"",VLOOKUP(G18,sf.V!$A$3:$K$124,11,FALSE),"")
C19: 4 | D19: =IF(G19<>"",VLOOKUP(G19,sf.V!$A$3:$K$124,3,FALSE),"") | E19: =IF(G19<>"",VLOOKUP(G19,sf.V!$A$3:$K$124,2,FALSE),"") | O19: =IF(G19<>"",VLOOKUP(G19,sf.V!$A$3:$K$124,6,FALSE)+N19,"") | P19: =IF(G19="","",IF(O19<T19,VLOOKUP(G19,sf.V!$A$3:$K$124,9,FALSE),IF(O19>=T19,VLOOKUP(G19,sf.V!$A$3:$K$124,10,FALSE),""))) | T19: =IF(G19<>"",VLOOKUP(G19,sf.V!$A$3:$K$124,11,FALSE),"")
C20: 5 | D20: =IF(G20<>"",VLOOKUP(G20,sf.V!$A$3:$K$124,3,FALSE),"") | E20: =IF(G20<>"",VLOOKUP(G20,sf.V!$A$3:$K$124,2,FALSE),"") | O20: =IF(G20<>"",VLOOKUP(G20,sf.V!$A$3:$K$124,6,FALSE)+N20,"") | P20: =IF(G20="","",IF(O20<T20,VLOOKUP(G20,sf.V!$A$3:$K$124,9,FALSE),IF(O20>=T20,VLOOKUP(G20,sf.V!$A$3:$K$124,10,FALSE),""))) | T20: =IF(G20<>"",VLOOKUP(G20,sf.V!$A$3:$K$124,11,FALSE),"")
C21: 6 | D21: =IF(G21<>"",VLOOKUP(G21,sf.V!$A$3:$K$124,3,FALSE),"") | E21: =IF(G21<>"",VLOOKUP(G21,sf.V!$A$3:$K$124,2,FALSE),"") | O21: =IF(G21<>"",VLOOKUP(G21,sf.V!$A$3:$K$124,6,FALSE)+N21,"") | P21: =IF(G21="","",IF(O21<T21,VLOOKUP(G21,sf.V!$A$3:$K$124,9,FALSE),IF(O21>=T21,VLOOKUP(G21,sf.V!$A$3:$K$124,10,FALSE),""))) | T21: =IF(G21<>"",VLOOKUP(G21,sf.V!$A$3:$K$124,11,FALSE),"")
C22: 7 | D22: =IF(G22<>"",VLOOKUP(G22,sf.V!$A$3:$K$124,3,FALSE),"") | E22: =IF(G22<>"",VLOOKUP(G22,sf.V!$A$3:$K$124,2,FALSE),"") | O22: =IF(G22<>"",VLOOKUP(G22,sf.V!$A$3:$K$124,6,FALSE)+N22,"") | P22: =IF(G22="","",IF(O22<T22,VLOOKUP(G22,sf.V!$A$3:$K$124,9,FALSE),IF(O22>=T22,VLOOKUP(G22,sf.V!$A$3:$K$124,10,FALSE),""))) | T22: =IF(G22<>"",VLOOKUP(G22,sf.V!$A$3:$K$124,11,FALSE),"")
C23: 8 | D23: =IF(G23<>"",VLOOKUP(G23,sf.V!$A$3:$K$124,3,FALSE),"") | E23: =IF(G23<>"",VLOOKUP(G23,sf.V!$A$3:$K$124,2,FALSE),"") | O23: =IF(G23<>"",VLOOKUP(G23,sf.V!$A$3:$K$124,6,FALSE)+N23,"") | P23: =IF(G23="","",IF(O23<T23,VLOOKUP(G23,sf.V!$A$3:$K$124,9,FALSE),IF(O23>=T23,VLOOKUP(G23,sf.V!$A$3:$K$124,10,FALSE),""))) | T23: =IF(G23<>"",VLOOKUP(G23,sf.V!$A$3:$K$124,11,FALSE),"")
C24: 9 | D24: =IF(G24<>"",VLOOKUP(G24,sf.V!$A$3:$K$124,3,FALSE),"") | E24: =IF(G24<>"",VLOOKUP(G24,sf.V!$A$3:$K$124,2,FALSE),"") | O24: =IF(G24<>"",VLOOKUP(G24,sf.V!$A$3:$K$124,6,FALSE)+N24,"") | P24: =IF(G24="","",IF(O24<T24,VLOOKUP(G24,sf.V!$A$3:$K$124,9,FALSE),IF(O24>=T24,VLOOKUP(G24,sf.V!$A$3:$K$124,10,FALSE),""))) | T24: =IF(G24<>"",VLOOKUP(G24,sf.V!$A$3:$K$124,11,FALSE),"")
C25: 10 | D25: =IF(G25<>"",VLOOKUP(G25,sf.V!$A$3:$K$124,3,FALSE),"") | E25: =IF(G25<>"",VLOOKUP(G25,sf.V!$A$3:$K$124,2,FALSE),"") | O25: =IF(G25<>"",VLOOKUP(G25,sf.V!$A$3:$K$124,6,FALSE)+N25,"") | P25: =IF(G25="","",IF(O25<T25,VLOOKUP(G25,sf.V!$A$3:$K$124,9,FALSE),IF(O25>=T25,VLOOKUP(G25,sf.V!$A$3:$K$124,10,FALSE),""))) | T25: =IF(G25<>"",VLOOKUP(G25,sf.V!$A$3:$K$124,11,FALSE),"")
C26: 11 | D26: =IF(G26<>"",VLOOKUP(G26,sf.V!$A$3:$K$124,3,FALSE),"") | E26: =IF(G26<>"",VLOOKUP(G26,sf.V!$A$3:$K$124,2,FALSE),"") | O26: =IF(G26<>"",VLOOKUP(G26,sf.V!$A$3:$K$124,6,FALSE)+N26,"") | P26: =IF(G26="","",IF(O26<T26,VLOOKUP(G26,sf.V!$A$3:$K$124,9,FALSE),IF(O26>=T26,VLOOKUP(G26,sf.V!$A$3:$K$124,10,FALSE),""))) | T26: =IF(G26<>"",VLOOKUP(G26,sf.V!$A$3:$K$124,11,FALSE),"")
C27: 12 | D27: =IF(G27<>"",VLOOKUP(G27,sf.V!$A$3:$K$124,3,FALSE),"") | E27: =IF(G27<>"",VLOOKUP(G27,sf.V!$A$3:$K$124,2,FALSE),"") | O27: =IF(G27<>"",VLOOKUP(G27,sf.V!$A$3:$K$124,6,FALSE)+N27,"") | P27: =IF(G27="","",IF(O27<T27,VLOOKUP(G27,sf.V!$A$3:$K$124,9,FALSE),IF(O27>=T27,VLOOKUP(G27,sf.V!$A$3:$K$124,10,FALSE),""))) | T27: =IF(G27<>"",VLOOKUP(G27,sf.V!$A$3:$K$124,11,FALSE),"")
C28: 13 | D28: =IF(G28<>"",VLOOKUP(G28,sf.V!$A$3:$K$124,3,FALSE),"") | E28: =IF(G28<>"",VLOOKUP(G28,sf.V!$A$3:$K$124,2,FALSE),"") | O28: =IF(G28<>"",VLOOKUP(G28,sf.V!$A$3:$K$124,6,FALSE)+N28,"") | P28: =IF(G28="","",IF(O28<T28,VLOOKUP(G28,sf.V!$A$3:$K$124,9,FALSE),IF(O28>=T28,VLOOKUP(G28,sf.V!$A$3:$K$124,10,FALSE),""))) | T28: =IF(G28<>"",VLOOKUP(G28,sf.V!$A$3:$K$124,11,FALSE),"")
C29: 14 | D29: =IF(G29<>"",VLOOKUP(G29,sf.V!$A$3:$K$124,3,FALSE),"") | E29: =IF(G29<>"",VLOOKUP(G29,sf.V!$A$3:$K$124,2,FALSE),"") | O29: =IF(G29<>"",VLOOKUP(G29,sf.V!$A$3:$K$124,6,FALSE)+N29,"") | P29: =IF(G29="","",IF(O29<T29,VLOOKUP(G29,sf.V!$A$3:$K$124,9,FALSE),IF(O29>=T29,VLOOKUP(G29,sf.V!$A$3:$K$124,10,FALSE),""))) | T29: =IF(G29<>"",VLOOKUP(G29,sf.V!$A$3:$K$124,11,FALSE),"")
C30: 15 | D30: =IF(G30<>"",VLOOKUP(G30,sf.V!$A$3:$K$124,3,FALSE),"") | E30: =IF(G30<>"",VLOOKUP(G30,sf.V!$A$3:$K$124,2,FALSE),"") | O30: =IF(G30<>"",VLOOKUP(G30,sf.V!$A$3:$K$124,6,FALSE)+N30,"") | P30: =IF(G30="","",IF(O30<T30,VLOOKUP(G30,sf.V!$A$3:$K$124,9,FALSE),IF(O30>=T30,VLOOKUP(G30,sf.V!$A$3:$K$124,10,FALSE),""))) | T30: =IF(G30<>"",VLOOKUP(G30,sf.V!$A$3:$K$124,11,FALSE),"")
... C35: 20 | D35: =IF(G35<>"",VLOOKUP(G35,sf.V!$A$3:$K$124,3,FALSE),"") | E35: =IF(G35<>"",VLOOKUP(G35,sf.V!$A$3:$K$124,2,FALSE),"") | O35: =IF(G35<>"",VLOOKUP(G35,sf.V!$A$3:$K$124,6,FALSE)+N35,"") | P35: =IF(G35="","",IF(O35<T35,VLOOKUP(G35,sf.V!$A$3:$K$124,9,FALSE),IF(O35>=T35,VLOOKUP(G35,sf.V!$A$3:$K$124,10,FALSE),""))) | T35: =IF(G35<>"",VLOOKUP(G35,sf.V!$A$3:$K$124,11,FALSE),"")
C36: 21 | D36: =IF(G36<>"",VLOOKUP(G36,sf.V!$A$3:$K$124,3,FALSE),"") | E36: =IF(G36<>"",VLOOKUP(G36,sf.V!$A$3:$K$124,2,FALSE),"") | F36: =IF(G36<>"",VLOOKUP(G36,sf.V!$A$3:$K$124,5,FALSE),"") | O36: =IF(G36<>"",VLOOKUP(G36,sf.V!$A$3:$K$124,6,FALSE)+N36,"") | P36: =IF(G36="","",IF(O36<T36,VLOOKUP(G36,sf.V!$A$3:$K$124,9,FALSE),IF(O36>=T36,VLOOKUP(G36,sf.V!$A$3:$K$124,10,FALSE),""))) | T36: =IF(G36<>"",VLOOKUP(G36,sf.V!$A$3:$K$124,11,FALSE),"")
C37: 22 | D37: =IF(G37<>"",VLOOKUP(G37,sf.V!$A$3:$K$124,3,FALSE),"") | E37: =IF(G37<>"",VLOOKUP(G37,sf.V!$A$3:$K$124,2,FALSE),"") | F37: =IF(G37<>"",VLOOKUP(G37,sf.V!$A$3:$K$124,5,FALSE),"") | O37: =IF(G37<>"",VLOOKUP(G37,sf.V!$A$3:$K$124,6,FALSE)+N37,"") | P37: =IF(G37="","",IF(O37<T37,VLOOKUP(G37,sf.V!$A$3:$K$124,9,FALSE),IF(O37>=T37,VLOOKUP(G37,sf.V!$A$3:$K$124,10,FALSE),""))) | T37: =IF(G37<>"",VLOOKUP(G37,sf.V!$A$3:$K$124,11,FALSE),"")
C38: 23 | D38: =IF(G38<>"",VLOOKUP(G38,sf.V!$A$3:$K$124,3,FALSE),"") | E38: =IF(G38<>"",VLOOKUP(G38,sf.V!$A$3:$K$124,2,FALSE),"") | F38: =IF(G38<>"",VLOOKUP(G38,sf.V!$A$3:$K$124,5,FALSE),"") | O38: =IF(G38<>"",VLOOKUP(G38,sf.V!$A$3:$K$124,6,FALSE)+N38,"") | P38: =IF(G38="","",IF(O38<T38,VLOOKUP(G38,sf.V!$A$3:$K$124,9,FALSE),IF(O38>=T38,VLOOKUP(G38,sf.V!$A$3:$K$124,10,FALSE),""))) | T38: =IF(G38<>"",VLOOKUP(G38,sf.V!$A$3:$K$124,11,FALSE),"")
C39: 24 | D39: =IF(G39<>"",VLOOKUP(G39,sf.V!$A$3:$K$124,3,FALSE),"") | E39: =IF(G39<>"",VLOOKUP(G39,sf.V!$A$3:$K$124,2,FALSE),"") | F39: =IF(G39<>"",VLOOKUP(G39,sf.V!$A$3:$K$124,5,FALSE),"") | O39: =IF(G39<>"",VLOOKUP(G39,sf.V!$A$3:$K$124,6,FALSE)+N39,"") | P39: =IF(G39="","",IF(O39<T39,VLOOKUP(G39,sf.V!$A$3:$K$124,9,FALSE),IF(O39>=T39,VLOOKUP(G39,sf.V!$A$3:$K$124,10,FALSE),""))) | T39: =IF(G39<>"",VLOOKUP(G39,sf.V!$A$3:$K$124,11,FALSE),"")
C40: 25 | D40: =IF(G40<>"",VLOOKUP(G40,sf.V!$A$3:$K$124,3,FALSE),"") | E40: =IF(G40<>"",VLOOKUP(G40,sf.V!$A$3:$K$124,2,FALSE),"") | F40: =IF(G40<>"",VLOOKUP(G40,sf.V!$A$3:$K$124,5,FALSE),"") | O40: =IF(G40<>"",VLOOKUP(G40,sf.V!$A$3:$K$124,6,FALSE)+N40,"") | P40: =IF(G40="","",IF(O40<T40,VLOOKUP(G40,sf.V!$A$3:$K$124,9,FALSE),IF(O40>=T40,VLOOKUP(G40,sf.V!$A$3:$K$124,10,FALSE),""))) | T40: =IF(G40<>"",VLOOKUP(G40,sf.V!$A$3:$K$124,11,FALSE),"")
C41: 26 | D41: =IF(G41<>"",VLOOKUP(G41,sf.V!$A$3:$K$124,3,FALSE),"") | E41: =IF(G41<>"",VLOOKUP(G41,sf.V!$A$3:$K$124,2,FALSE),"") | F41: =IF(G41<>"",VLOOKUP(G41,sf.V!$A$3:$K$124,5,FALSE),"") | O41: =IF(G41<>"",VLOOKUP(G41,sf.V!$A$3:$K$124,6,FALSE)+N41,"") | P41: =IF(G41="","",IF(O41<T41,VLOOKUP(G41,sf.V!$A$3:$K$124,9,FALSE),IF(O41>=T41,VLOOKUP(G41,sf.V!$A$3:$K$124,10,FALSE),""))) | T41: =IF(G41<>"",VLOOKUP(G41,sf.V!$A$3:$K$124,11,FALSE),"")
C42: 27 | D42: =IF(G42<>"",VLOOKUP(G42,sf.V!$A$3:$K$124,3,FALSE),"") | E42: =IF(G42<>"",VLOOKUP(G42,sf.V!$A$3:$K$124,2,FALSE),"") | F42: =IF(G42<>"",VLOOKUP(G42,sf.V!$A$3:$K$124,5,FALSE),"") | O42: =IF(G42<>"",VLOOKUP(G42,sf.V!$A$3:$K$124,6,FALSE)+N42,"") | P42: =IF(G42="","",IF(O42<T42,VLOOKUP(G42,sf.V!$A$3:$K$124,9,FALSE),IF(O42>=T42,VLOOKUP(G42,sf.V!$A$3:$K$124,10,FALSE),""))) | T42: =IF(G42<>"",VLOOKUP(G42,sf.V!$A$3:$K$124,11,FALSE),"")
C43: 28 | D43: =IF(G43<>"",VLOOKUP(G43,sf.V!$A$3:$K$124,3,FALSE),"") | E43: =IF(G43<>"",VLOOKUP(G43,sf.V!$A$3:$K$124,2,FALSE),"") | F43: =IF(G43<>"",VLOOKUP(G43,sf.V!$A$3:$K$124,5,FALSE),"") | O43: =IF(G43<>"",VLOOKUP(G43,sf.V!$A$3:$K$124,6,FALSE)+N43,"") | P43: =IF(G43="","",IF(O43<T43,VLOOKUP(G43,sf.V!$A$3:$K$124,9,FALSE),IF(O43>=T43,VLOOKUP(G43,sf.V!$A$3:$K$124,10,FALSE),""))) | T43: =IF(G43<>"",VLOOKUP(G43,sf.V!$A$3:$K$124,11,FALSE),"")
C44: 29 | D44: =IF(G44<>"",VLOOKUP(G44,sf.V!$A$3:$K$124,3,FALSE),"") | E44: =IF(G44<>"",VLOOKUP(G44,sf.V!$A$3:$K$124,2,FALSE),"") | F44: =IF(G44<>"",VLOOKUP(G44,sf.V!$A$3:$K$124,5,FALSE),"") | O44: =IF(G44<>"",VLOOKUP(G44,sf.V!$A$3:$K$124,6,FALSE)+N44,"") | P44: =IF(G44="","",IF(O44<T44,VLOOKUP(G44,sf.V!$A$3:$K$124,9,FALSE),IF(O44>=T44,VLOOKUP(G44,sf.V!$A$3:$K$124,10,FALSE),""))) | T44: =IF(G44<>"",VLOOKUP(G44,sf.V!$A$3:$K$124,11,FALSE),"")
C45: 30 | D45: =IF(G45<>"",VLOOKUP(G45,sf.V!$A$3:$K$124,3,FALSE),"") | E45: =IF(G45<>"",VLOOKUP(G45,sf.V!$A$3:$K$124,2,FALSE),"") | F45: =IF(G45<>"",VLOOKUP(G45,sf.V!$A$3:$K$124,5,FALSE),"") | O45: =IF(G45<>"",VLOOKUP(G45,sf.V!$A$3:$K$124,6,FALSE)+N45,"") | P45: =IF(G45="","",IF(O45<T45,VLOOKUP(G45,sf.V!$A$3:$K$124,9,FALSE),IF(O45>=T45,VLOOKUP(G45,sf.V!$A$3:$K$124,10,FALSE),""))) | T45: =IF(G45<>"",VLOOKUP(G45,sf.V!$A$3:$K$124,11,FALSE),"")
C46: 31 | D46: =IF(G46<>"",VLOOKUP(G46,sf.V!$A$3:$K$124,3,FALSE),"") | E46: =IF(G46<>"",VLOOKUP(G46,sf.V!$A$3:$K$124,2,FALSE),"") | F46: =IF(G46<>"",VLOOKUP(G46,sf.V!$A$3:$K$124,5,FALSE),"") | O46: =IF(G46<>"",VLOOKUP(G46,sf.V!$A$3:$K$124,6,FALSE)+N46,"") | P46: =IF(G46="","",IF(O46<T46,VLOOKUP(G46,sf.V!$A$3:$K$124,9,FALSE),IF(O46>=T46,VLOOKUP(G46,sf.V!$A$3:$K$124,10,FALSE),""))) | T46: =IF(G46<>"",VLOOKUP(G46,sf.V!$A$3:$K$124,11,FALSE),"")
C47: 32 | D47: =IF(G47<>"",VLOOKUP(G47,sf.V!$A$3:$K$124,3,FALSE),"") | E47: =IF(G47<>"",VLOOKUP(G47,sf.V!$A$3:$K$124,2,FALSE),"") | F47: =IF(G47<>"",VLOOKUP(G47,sf.V!$A$3:$K$124,5,FALSE),"") | O47: =IF(G47<>"",VLOOKUP(G47,sf.V!$A$3:$K$124,6,FALSE)+N47,"") | P47: =IF(G47="","",IF(O47<T47,VLOOKUP(G47,sf.V!$A$3:$K$124,9,FALSE),IF(O47>=T47,VLOOKUP(G47,sf.V!$A$3:$K$124,10,FALSE),""))) | T47: =IF(G47<>"",VLOOKUP(G47,sf.V!$A$3:$K$124,11,FALSE),"")
... C64: 49 | D64: =IF(G64<>"",VLOOKUP(G64,sf.V!$A$3:$K$124,3,FALSE),"") | E64: =IF(G64<>"",VLOOKUP(G64,sf.V!$A$3:$K$124,2,FALSE),"") | F64: =IF(G64<>"",VLOOKUP(G64,sf.V!$A$3:$K$124,5,FALSE),"") | O64: =IF(G64<>"",VLOOKUP(G64,sf.V!$A$3:$K$124,6,FALSE)+N64,"") | P64: =IF(G64="","",IF(O64<T64,VLOOKUP(G64,sf.V!$A$3:$K$124,9,FALSE),IF(O64>=T64,VLOOKUP(G64,sf.V!$A$3:$K$124,10,FALSE),""))) | T64: =IF(G64<>"",VLOOKUP(G64,sf.V!$A$3:$K$124,11,FALSE),"")
...
